// Error scenario tests for sync monitoring system
// Story 2.3: Comprehensive error handling validation

import { assertEquals, assertExists } from "https://deno.land/std@0.168.0/testing/asserts.ts"

// Mock error scenarios
const ERROR_SCENARIOS = {
  NETWORK_TIMEOUT: {
    name: 'Network timeout during sync',
    error: new Error('ETIMEDOUT: Connection timeout'),
    type: 'NETWORK',
    severity: 'HIGH',
    recoverable: true
  },
  DATABASE_CONNECTION: {
    name: 'Database connection failure',
    error: new Error('Connection to database failed'),
    type: 'DATABASE',
    severity: 'CRITICAL',
    recoverable: true
  },
  API_AUTHENTICATION: {
    name: 'API authentication failure',
    error: new Error('401 Unauthorized'),
    type: 'AUTHENTICATION',
    severity: 'HIGH',
    recoverable: true
  },
  MEMORY_EXHAUSTION: {
    name: 'Memory exhaustion during sync',
    error: new Error('JavaScript heap out of memory'),
    type: 'SYSTEM',
    severity: 'CRITICAL',
    recoverable: false
  },
  DATA_CORRUPTION: {
    name: 'Data corruption detected',
    error: new Error('Invalid data format received'),
    type: 'VALIDATION',
    severity: 'HIGH',
    recoverable: false
  },
  RATE_LIMITING: {
    name: 'API rate limit exceeded',
    error: new Error('429 Too Many Requests'),
    type: 'API',
    severity: 'MEDIUM',
    recoverable: true
  }
}

// Mock error simulation utilities
class ErrorSimulator {
  static async simulateNetworkError(): Promise<never> {
    await new Promise(resolve => setTimeout(resolve, 100))
    throw ERROR_SCENARIOS.NETWORK_TIMEOUT.error
  }

  static async simulateDatabaseError(): Promise<never> {
    await new Promise(resolve => setTimeout(resolve, 50))
    throw ERROR_SCENARIOS.DATABASE_CONNECTION.error
  }

  static async simulateAuthenticationError(): Promise<never> {
    await new Promise(resolve => setTimeout(resolve, 200))
    throw ERROR_SCENARIOS.API_AUTHENTICATION.error
  }

  static async simulateMemoryError(): Promise<never> {
    await new Promise(resolve => setTimeout(resolve, 300))
    throw ERROR_SCENARIOS.MEMORY_EXHAUSTION.error
  }

  static async simulateValidationError(): Promise<never> {
    await new Promise(resolve => setTimeout(resolve, 75))
    throw ERROR_SCENARIOS.DATA_CORRUPTION.error
  }

  static async simulateRateLimitError(): Promise<never> {
    await new Promise(resolve => setTimeout(resolve, 150))
    throw ERROR_SCENARIOS.RATE_LIMITING.error
  }
}

// Mock error recovery handler
class ErrorRecoveryHandler {
  private recoveryAttempts = new Map<string, number>()
  
  async handleError(error: Error, context: any): Promise<any> {
    const errorType = this.classifyError(error)
    const attemptKey = `${errorType}-${context.sync_job_id || 'unknown'}`
    
    const attempts = this.recoveryAttempts.get(attemptKey) || 0
    this.recoveryAttempts.set(attemptKey, attempts + 1)
    
    const scenario = Object.values(ERROR_SCENARIOS).find(s => s.error.message === error.message)
    
    if (!scenario?.recoverable || attempts >= 3) {
      return {
        recovery_attempted: scenario?.recoverable || false,
        recovery_successful: false,
        final_status: 'FAILED',
        attempts: attempts + 1,
        error_classification: errorType,
        recovery_suggestion: this.getRecoverySuggestion(errorType)
      }
    }
    
    // Simulate recovery attempt
    await new Promise(resolve => setTimeout(resolve, 500))
    
    const recoverySuccess = Math.random() > 0.3 // 70% recovery success rate
    
    if (recoverySuccess) {
      this.recoveryAttempts.delete(attemptKey)
      return {
        recovery_attempted: true,
        recovery_successful: true,
        final_status: 'COMPLETED',
        attempts: attempts + 1,
        error_classification: errorType
      }
    }
    
    throw error // Recovery failed, re-throw
  }
  
  private classifyError(error: Error): string {
    if (error.message.includes('timeout') || error.message.includes('ETIMEDOUT')) {
      return 'NETWORK'
    }
    if (error.message.includes('database') || error.message.includes('Connection')) {
      return 'DATABASE'
    }
    if (error.message.includes('401') || error.message.includes('Unauthorized')) {
      return 'AUTHENTICATION'
    }
    if (error.message.includes('heap') || error.message.includes('memory')) {
      return 'SYSTEM'
    }
    if (error.message.includes('Invalid') || error.message.includes('format')) {
      return 'VALIDATION'
    }
    if (error.message.includes('429') || error.message.includes('rate')) {
      return 'API'
    }
    return 'UNKNOWN'
  }
  
  private getRecoverySuggestion(errorType: string): string {
    const suggestions = {
      'NETWORK': 'Check network connectivity and retry with exponential backoff',
      'DATABASE': 'Verify database connection and check connection pool settings',
      'AUTHENTICATION': 'Refresh authentication tokens and verify API credentials',
      'SYSTEM': 'Reduce memory usage, implement pagination, or increase system resources',
      'VALIDATION': 'Validate data integrity and check API contract compatibility',
      'API': 'Implement rate limiting and retry with appropriate delays',
      'UNKNOWN': 'Review error logs and implement specific error handling'
    }
    return suggestions[errorType] || suggestions['UNKNOWN']
  }
}

Deno.test("Error Handling - Network timeout recovery", async () => {
  const recoveryHandler = new ErrorRecoveryHandler()
  
  const syncContext = {
    sync_job_id: 'network-error-test',
    entity_type: 'tournaments',
    tournament_no: 'T001'
  }
  
  let finalResult
  let attempts = 0
  
  // Attempt sync with network error simulation
  while (attempts < 5) {
    try {
      attempts++
      
      if (attempts <= 2) {
        // First two attempts fail with network error
        await ErrorSimulator.simulateNetworkError()
      } else {
        // Subsequent attempts succeed
        break
      }
      
    } catch (error) {
      try {
        finalResult = await recoveryHandler.handleError(error, syncContext)
        if (finalResult.recovery_successful) {
          break
        }
      } catch (recoveryError) {
        // Continue attempting recovery
        continue
      }
    }
  }
  
  // Verify error handling and recovery
  assertEquals(attempts > 1, true, 'Should require multiple attempts for network error')
  assertEquals(attempts <= 4, true, 'Should not exceed maximum recovery attempts')
  
  if (finalResult) {
    assertEquals(finalResult.recovery_attempted, true)
    assertEquals(finalResult.error_classification, 'NETWORK')
    assertExists(finalResult.recovery_suggestion)
    assertEquals(finalResult.recovery_suggestion.includes('network'), true)
  }
})

Deno.test("Error Handling - Database connection failure cascade", async () => {
  const recoveryHandler = new ErrorRecoveryHandler()
  
  // Test multiple database operations failing in sequence
  const operations = [
    { name: 'sync-execution-insert', sync_job_id: 'db-error-1' },
    { name: 'error-log-insert', sync_job_id: 'db-error-2' },
    { name: 'metrics-update', sync_job_id: 'db-error-3' }
  ]
  
  const results = []
  
  for (const operation of operations) {
    try {
      await ErrorSimulator.simulateDatabaseError()
    } catch (error) {
      const result = await recoveryHandler.handleError(error, operation)
      results.push({
        operation: operation.name,
        ...result
      })
    }
  }
  
  // Verify cascading error handling
  assertEquals(results.length, operations.length)
  
  for (const result of results) {
    assertEquals(result.error_classification, 'DATABASE')
    assertEquals(result.recovery_attempted, true)
    assertExists(result.recovery_suggestion)
    assertEquals(result.recovery_suggestion.includes('database'), true)
  }
  
  // At least some operations should eventually succeed with recovery
  const successfulRecoveries = results.filter(r => r.recovery_successful).length
  assertEquals(successfulRecoveries >= 1, true, 'At least one operation should recover successfully')
})

Deno.test("Error Handling - Authentication failure with token refresh", async () => {
  const recoveryHandler = new ErrorRecoveryHandler()
  
  const authContext = {
    sync_job_id: 'auth-error-test',
    entity_type: 'matches_schedule',
    api_endpoint: 'tournament-api'
  }
  
  // Simulate authentication error scenario
  let authResult
  try {
    await ErrorSimulator.simulateAuthenticationError()
  } catch (error) {
    authResult = await recoveryHandler.handleError(error, authContext)
  }
  
  assertExists(authResult)
  assertEquals(authResult.error_classification, 'AUTHENTICATION')
  assertEquals(authResult.recovery_attempted, true)
  assertEquals(authResult.recovery_suggestion.includes('authentication'), true)
  
  // Test token refresh simulation
  const tokenRefreshResult = {
    old_token_expired: true,
    new_token_obtained: authResult.recovery_successful,
    token_refresh_duration: 1500, // ms
    retry_after_refresh: authResult.recovery_successful
  }
  
  assertEquals(typeof tokenRefreshResult.new_token_obtained, 'boolean')
  assertEquals(tokenRefreshResult.token_refresh_duration < 5000, true, 'Token refresh should complete quickly')
})

Deno.test("Error Handling - Memory exhaustion non-recoverable error", async () => {
  const recoveryHandler = new ErrorRecoveryHandler()
  
  const memoryContext = {
    sync_job_id: 'memory-error-test',
    entity_type: 'tournaments',
    records_in_memory: 100000,
    memory_usage_mb: 512
  }
  
  // Memory errors should not be recoverable through retry
  let memoryResult
  try {
    await ErrorSimulator.simulateMemoryError()
  } catch (error) {
    memoryResult = await recoveryHandler.handleError(error, memoryContext)
  }
  
  assertExists(memoryResult)
  assertEquals(memoryResult.error_classification, 'SYSTEM')
  assertEquals(memoryResult.recovery_attempted, false, 'Memory errors should not attempt automatic recovery')
  assertEquals(memoryResult.final_status, 'FAILED')
  assertEquals(memoryResult.recovery_suggestion.includes('memory'), true)
  assertEquals(memoryResult.recovery_suggestion.includes('resources'), true)
  
  // Verify memory error handling provides specific guidance
  const memoryGuidance = memoryResult.recovery_suggestion
  assertEquals(memoryGuidance.includes('pagination') || memoryGuidance.includes('reduce'), true,
    'Memory error should suggest pagination or reduction strategies')
})

Deno.test("Error Handling - Data validation error with detailed analysis", async () => {
  const recoveryHandler = new ErrorRecoveryHandler()
  
  const validationContext = {
    sync_job_id: 'validation-error-test',
    entity_type: 'tournaments',
    invalid_records: [
      { tournament_no: null, error: 'Missing required field' },
      { start_date: '2025-13-40', error: 'Invalid date format' },
      { status: 'INVALID_STATUS', error: 'Unknown status value' }
    ]
  }
  
  let validationResult
  try {
    await ErrorSimulator.simulateValidationError()
  } catch (error) {
    validationResult = await recoveryHandler.handleError(error, validationContext)
  }
  
  assertExists(validationResult)
  assertEquals(validationResult.error_classification, 'VALIDATION')
  assertEquals(validationResult.recovery_attempted, false, 'Data validation errors should not auto-retry')
  assertEquals(validationResult.final_status, 'FAILED')
  
  // Validation errors should provide specific guidance
  const validationGuidance = validationResult.recovery_suggestion
  assertEquals(validationGuidance.includes('data integrity') || validationGuidance.includes('validate'), true)
  
  // Simulate detailed validation error analysis
  const detailedAnalysis = {
    total_records_processed: 1000,
    invalid_records_count: validationContext.invalid_records.length,
    validation_errors_by_type: {
      'missing_required_field': 1,
      'invalid_date_format': 1,
      'unknown_enum_value': 1
    },
    data_quality_score: 0.997, // (1000-3)/1000
    recommended_actions: [
      'Review data source quality',
      'Implement pre-sync validation',
      'Update data transformation logic'
    ]
  }
  
  assertEquals(detailedAnalysis.invalid_records_count, 3)
  assertEquals(detailedAnalysis.data_quality_score > 0.99, true)
  assertEquals(detailedAnalysis.recommended_actions.length, 3)
})

Deno.test("Error Handling - Rate limiting with exponential backoff", async () => {
  const recoveryHandler = new ErrorRecoveryHandler()
  
  const rateLimitContext = {
    sync_job_id: 'rate-limit-test',
    entity_type: 'matches_schedule',
    api_calls_per_minute: 120,
    current_rate_limit: 100
  }
  
  // Simulate multiple rate limit errors with backoff
  const backoffResults = []
  let currentDelay = 1000 // Start with 1 second
  
  for (let attempt = 1; attempt <= 4; attempt++) {
    const startTime = Date.now()
    
    try {
      await ErrorSimulator.simulateRateLimitError()
    } catch (error) {
      const result = await recoveryHandler.handleError(error, rateLimitContext)
      const endTime = Date.now()
      
      backoffResults.push({
        attempt,
        delay_before_retry: currentDelay,
        actual_delay: endTime - startTime,
        recovery_successful: result.recovery_successful,
        error_classification: result.error_classification
      })
      
      // Exponential backoff for next attempt
      currentDelay *= 2
      
      if (result.recovery_successful) {
        break
      }
    }
  }
  
  // Verify exponential backoff behavior
  assertEquals(backoffResults.length >= 1, true)
  
  for (const result of backoffResults) {
    assertEquals(result.error_classification, 'API')
    assertEquals(result.actual_delay >= result.delay_before_retry * 0.8, true, 
      'Actual delay should approximate expected backoff delay')
  }
  
  // At least one attempt should eventually succeed
  const successfulAttempt = backoffResults.find(r => r.recovery_successful)
  if (successfulAttempt) {
    assertEquals(successfulAttempt.recovery_successful, true)
  }
  
  console.log('Rate limit backoff results:', backoffResults.map(r => ({
    attempt: r.attempt,
    delay: r.delay_before_retry,
    success: r.recovery_successful
  })))
})

Deno.test("Error Handling - Circuit breaker pattern implementation", async () => {
  // Mock circuit breaker for external service calls
  class CircuitBreaker {
    private failureCount = 0
    private lastFailureTime = 0
    private state: 'CLOSED' | 'OPEN' | 'HALF_OPEN' = 'CLOSED'
    private readonly failureThreshold = 5
    private readonly timeoutWindow = 60000 // 1 minute
    
    async execute<T>(operation: () => Promise<T>): Promise<T> {
      if (this.state === 'OPEN') {
        if (Date.now() - this.lastFailureTime > this.timeoutWindow) {
          this.state = 'HALF_OPEN'
        } else {
          throw new Error('Circuit breaker is OPEN - service unavailable')
        }
      }
      
      try {
        const result = await operation()
        this.onSuccess()
        return result
      } catch (error) {
        this.onFailure()
        throw error
      }
    }
    
    private onSuccess() {
      this.failureCount = 0
      this.state = 'CLOSED'
    }
    
    private onFailure() {
      this.failureCount++
      this.lastFailureTime = Date.now()
      
      if (this.failureCount >= this.failureThreshold) {
        this.state = 'OPEN'
      }
    }
    
    getState() {
      return {
        state: this.state,
        failureCount: this.failureCount,
        lastFailureTime: this.lastFailureTime
      }
    }
  }
  
  const circuitBreaker = new CircuitBreaker()
  const operationResults = []
  
  // Test circuit breaker with multiple failing operations
  for (let i = 0; i < 10; i++) {
    try {
      await circuitBreaker.execute(async () => {
        if (i < 6) {
          // First 6 operations fail
          throw new Error(`Network error ${i}`)
        } else {
          // Later operations succeed
          return { success: true, operation: i }
        }
      })
      
      operationResults.push({ operation: i, result: 'SUCCESS', state: circuitBreaker.getState().state })
      
    } catch (error) {
      operationResults.push({ 
        operation: i, 
        result: 'FAILED', 
        error: error.message, 
        state: circuitBreaker.getState().state 
      })
    }
  }
  
  // Verify circuit breaker behavior
  const failedOps = operationResults.filter(r => r.result === 'FAILED')
  const successfulOps = operationResults.filter(r => r.result === 'SUCCESS')
  const circuitOpenOps = operationResults.filter(r => r.state === 'OPEN')
  
  assertEquals(failedOps.length >= 5, true, 'Should have multiple failures before circuit opens')
  assertEquals(circuitOpenOps.length >= 1, true, 'Circuit should open after failure threshold')
  assertEquals(successfulOps.length >= 1, true, 'Should have some successful operations after recovery')
  
  console.log('Circuit breaker test results:', operationResults.map(r => ({
    op: r.operation,
    result: r.result,
    state: r.state
  })))
})

Deno.test("Error Handling - Error aggregation and trend analysis", async () => {
  const recoveryHandler = new ErrorRecoveryHandler()
  
  // Simulate multiple errors over time for trend analysis
  const errorLog = []
  const timeWindow = 24 * 60 * 60 * 1000 // 24 hours
  const currentTime = Date.now()
  
  // Generate error scenarios over time
  const errorTypes = ['NETWORK', 'DATABASE', 'AUTHENTICATION', 'API', 'VALIDATION']
  
  for (let i = 0; i < 50; i++) {
    const errorTime = currentTime - Math.random() * timeWindow
    const errorType = errorTypes[Math.floor(Math.random() * errorTypes.length)]
    const severity = ['LOW', 'MEDIUM', 'HIGH', 'CRITICAL'][Math.floor(Math.random() * 4)]
    
    errorLog.push({
      timestamp: new Date(errorTime).toISOString(),
      error_type: errorType,
      severity,
      entity_type: ['tournaments', 'matches_schedule'][Math.floor(Math.random() * 2)],
      recovery_attempted: Math.random() > 0.3,
      recovery_successful: Math.random() > 0.4,
      impact_duration_minutes: Math.floor(Math.random() * 30) + 1
    })
  }
  
  // Analyze error trends
  const errorAnalysis = {
    total_errors: errorLog.length,
    errors_by_type: errorTypes.reduce((acc, type) => {
      acc[type] = errorLog.filter(e => e.error_type === type).length
      return acc
    }, {} as Record<string, number>),
    errors_by_severity: ['LOW', 'MEDIUM', 'HIGH', 'CRITICAL'].reduce((acc, severity) => {
      acc[severity] = errorLog.filter(e => e.severity === severity).length
      return acc
    }, {} as Record<string, number>),
    recovery_success_rate: errorLog.filter(e => e.recovery_attempted && e.recovery_successful).length / 
                          errorLog.filter(e => e.recovery_attempted).length,
    avg_impact_duration: errorLog.reduce((sum, e) => sum + e.impact_duration_minutes, 0) / errorLog.length,
    critical_errors: errorLog.filter(e => e.severity === 'CRITICAL'),
    error_rate_last_hour: errorLog.filter(e => 
      Date.now() - new Date(e.timestamp).getTime() < 60 * 60 * 1000
    ).length
  }
  
  // Verify error analysis
  assertEquals(errorAnalysis.total_errors, 50)
  assertEquals(typeof errorAnalysis.recovery_success_rate, 'number')
  assertEquals(errorAnalysis.recovery_success_rate >= 0 && errorAnalysis.recovery_success_rate <= 1, true)
  assertEquals(errorAnalysis.avg_impact_duration > 0, true)
  assertEquals(Array.isArray(errorAnalysis.critical_errors), true)
  
  // Error trends should provide actionable insights
  const mostCommonErrorType = Object.entries(errorAnalysis.errors_by_type)
    .reduce((a, b) => a[1] > b[1] ? a : b)[0]
  const criticalErrorRate = errorAnalysis.critical_errors.length / errorAnalysis.total_errors
  
  assertExists(mostCommonErrorType)
  assertEquals(criticalErrorRate >= 0, true)
  assertEquals(criticalErrorRate <= 1, true)
  
  console.log('Error trend analysis:', {
    totalErrors: errorAnalysis.total_errors,
    mostCommonType: mostCommonErrorType,
    recoverySuccessRate: (errorAnalysis.recovery_success_rate * 100).toFixed(1) + '%',
    criticalErrorRate: (criticalErrorRate * 100).toFixed(1) + '%',
    avgImpactMinutes: errorAnalysis.avg_impact_duration.toFixed(1)
  })
})